Workbook

Sheet Invoice — Region 2
A1: SITHEMBE TRANSPORTATION & PROJECTS | G1: Tax Invoice
A3: Tel: 012 880 3155 | Cell: 073 124 1535 | Fax: 086 603 7935 | E3: Tax Invoice No: | H3: STP/INV/26/0353
A4: Email: accounts@sithembe.co.za | info@sithembe.co.za | E4: Invoice Date: | H4: 46107
A5: VAToilet Number: 4070272101 | Vendor No: 101776 | E5: Service Period: | H5: 01 Mar 2026 - 25 Mar 2026
A6: Reg No: 2013/029173/07 | www.sithembe.co.za | E6: Region: | H6: Region 2
A7: Contract Ref: HS 02-2025/26
A10: BILL TO:
A11: City of Tshwane
A12: PO Box 6338
A13: Pretoria
A14: 0001
A16: VAT Number: 4000142267
A17: Tel: 012 358 3368
A19: # | B19: TOWNSHIP / INFORMAL SETTLEMENT | C19: RENTALS & RELOCATIONS | F19: SERVICE | H19: SUB TOTALS
B20: TOWNSHIP / INFORMAL SETTLEMENT | C20: Qty (Units) | D20: Days in Period | E20: Rental Amount R11.50 | F20: No of Services | G20: Service Amount R96.50
A21: 1 | B21: Themba View Ext 1 | C21: 1 | D21: 23 | E21: =IF(C21="","",C21*D21*11.5) -> 264.5 | F21: ='Service Notes'!J8 -> 5 | G21: =IF(C21="","",C21*F21*96.5) -> 482.5 | H21: =IF(C21="","",E21+G21) -> 747
A22: 2 | B22: Themba View Ext 1 | C22: 7 | D22: 24 | E22: =IF(C22="","",C22*D22*11.5) -> 1932 | F22: ='Service Notes'!J9 -> 5 | G22: =IF(C22="","",C22*F22*96.5) -> 3377.5 | H22: =IF(C22="","",E22+G22) -> 5309.5
A23: 3 | B23: Marokolong | C23: 11 | D23: 23 | E23: =IF(C23="","",C23*D23*11.5) -> 2909.5 | F23: 5 | G23: =IF(C23="","",C23*F23*96.5) -> 5307.5 | H23: =IF(C23="","",E23+G23) -> 8217
A24: 4 | B24: Hammanskraal Ext 4 | C24: 16 | D24: 25 | E24: =IF(C24="","",C24*D24*11.5) -> 4600 | F24: ='Service Notes'!J11 -> 6 | G24: =IF(C24="","",C24*F24*96.5) -> 9264 | H24: =IF(C24="","",E24+G24) -> 13864
A25: 5 | B25: Hammanskraal Ext 4 | C25: 14 | D25: 24 | E25: =IF(C25="","",C25*D25*11.5) -> 3864 | F25: ='Service Notes'!J12 -> 5 | G25: =IF(C25="","",C25*F25*96.5) -> 6755 | H25: =IF(C25="","",E25+G25) -> 10619
A26: 6 | B26: Hammanskraal portion 9 & 10 | C26: 160 | D26: 25 | E26: =IF(C26="","",C26*D26*11.5) -> 46000 | F26: ='Service Notes'!J13 -> 6 | G26: =IF(C26="","",C26*F26*96.5) -> 92640 | H26: =IF(C26="","",E26+G26) -> 138640
A27: 7 | B27: Soshanguve X Buffer C | C27: 50 | D27: 24 | E27: =IF(C27="","",C27*D27*11.5) -> 13800 | F27: ='Service Notes'!J14 -> 5 | G27: =IF(C27="","",C27*F27*96.5) -> 24125 | H27: =IF(C27="","",E27+G27) -> 37925
A28: 8 | B28: Soshanguve X Buffer D | C28: 60 | D28: 25 | E28: =IF(C28="","",C28*D28*11.5) -> 17250 | F28: ='Service Notes'!J15 -> 6 | G28: =IF(C28="","",C28*F28*96.5) -> 34740 | H28: =IF(C28="","",E28+G28) -> 51990
A29: 9 | B29: Soshanguve X Buffer Civcon | C29: 10 | D29: 23 | E29: =IF(C29="","",C29*D29*11.5) -> 2645 | F29: ='Service Notes'!J16 -> 5 | G29: =IF(C29="","",C29*F29*96.5) -> 4825 | H29: =IF(C29="","",E29+G29) -> 7470
A30: 10 | B30: Dali Mpofu | C30: 40 | D30: 25 | E30: =IF(C30="","",C30*D30*11.5) -> 11500 | F30: ='Service Notes'!J17 -> 6 | G30: =IF(C30="","",C30*F30*96.5) -> 23160 | H30: =IF(C30="","",E30+G30) -> 34660
A31: 11 | B31: Stinkwater | C31: 3 | D31: 23 | E31: =IF(C31="","",C31*D31*11.5) -> 793.5 | F31: ='Service Notes'!J18 -> 5 | G31: =IF(C31="","",C31*F31*96.5) -> 1447.5 | H31: =IF(C31="","",E31+G31) -> 2241
A32: 12 | B32: Stinkwater Ext 10 | C32: 70 | D32: 24 | E32: =IF(C32="","",C32*D32*11.5) -> 19320 | F32: ='Service Notes'!J19 -> 5 | G32: =IF(C32="","",C32*F32*96.5) -> 33775 | H32: =IF(C32="","",E32+G32) -> 53095
A33: 13 | B33: Chris Hani | C33: 80 | D33: 25 | E33: =IF(C33="","",C33*D33*11.5) -> 23000 | F33: ='Service Notes'!J20 -> 6 | G33: =IF(C33="","",C33*F33*96.5) -> 46320 | H33: =IF(C33="","",E33+G33) -> 69320
A34: 14 | B34: Phomolong Phase 1 | C34: 59 | D34: 24 | E34: =IF(C34="","",C34*D34*11.5) -> 16284 | F34: ='Service Notes'!J21 -> 5 | G34: =IF(C34="","",C34*F34*96.5) -> 28467.5 | H34: =IF(C34="","",E34+G34) -> 44751.5
A35: 15 | B35: Greenfield Ext 14 (Lefika Camp) | C35: 15 | D35: 23 | E35: =IF(C35="","",C35*D35*11.5) -> 3967.5 | F35: ='Service Notes'!J22 -> 5 | G35: =IF(C35="","",C35*F35*96.5) -> 7237.5 | H35: =IF(C35="","",E35+G35) -> 11205
D36: =IF(C36="","",$H$13) | E36: =IF(C36="","",C36*$H$13*$H$14) | G36: =IF(C36="","",C36*F36*$H$15) | H36: =IF(C36="","",E36+G36)
D37: =IF(C37="","",$H$13) | E37: =IF(C37="","",C37*$H$13*$H$14) | G37: =IF(C37="","",C37*F37*$H$15)
B39: Sub Totals | C39: =SUM(C21:C37) -> 596 | E39: =SUM(E21:E37) -> 168130 | G39: =SUM(G21:G37) -> 321924 | H39: =SUM(E39,G39) -> 490054 | I39: =SUM(H21:H35) -> 490054
G40: VAT @ 15% | H40: =H39*15% -> 73508.1
A41: BANKING DETAILS | F41: Gross Total | H41: =H39+H40 -> 563562.1
A42: Account Holder: Sithembe Transportation and Projects (Pty) Ltd
A43: Bank: Nedbank Limited
A44: AccounToilet Number: 1323687157
A45: Branch Code: 198765
E46: City of Tshwane Official:
...

Sheet Service Notes
A1: SITHEMBE TRANSPORTATION & PROJECTS | G1: Service Notes - Pump & Clean
A3: City of Thswane
A4: Hiring and Servicing of chemical toilets
A5: HS 02-2025/26
A6: Service Notes (From 1 March 2026 To 25 March 2026)
A7: TOWNSHIP / INFORMAL SETTLEMENT | C7: Qty (Units) | D7: THURSDAY | E7: MONDAY | F7: THURSDAY | G7: MONDAY | H7: THURSDAY | I7: MONDAY | J7: No of Service
A8: ='Invoice — Region 2'!B21 -> Themba View Ext 1 | C8: ='Invoice — Region 2'!C21 -> 1 | E8: 46090 | F8: 46093 | G8: 46097 | H8: 46100 | I8: 46104 | J8: =COUNT(D8:I8) -> 5
A9: ='Invoice — Region 2'!B22 -> Themba View Ext 1 | C9: ='Invoice — Region 2'!C22 -> 7 | E9: 46090 | F9: 46093 | G9: 46097 | H9: 46100 | I9: 46104 | J9: =COUNT(D9:I9) -> 5
A10: ='Invoice — Region 2'!B23 -> Marokolong | C10: ='Invoice — Region 2'!C23 -> 11 | E10: 46090 | F10: 46093 | G10: 46097 | H10: 46100 | I10: 46104 | J10: =COUNT(D10:I10) -> 5
A11: ='Invoice — Region 2'!B24 -> Hammanskraal Ext 4 | C11: ='Invoice — Region 2'!C24 -> 16 | D11: 46086 | E11: 46090 | F11: 46093 | G11: 46097 | H11: 46100 | I11: 46104 | J11: =COUNT(D11:I11) -> 6
A12: ='Invoice — Region 2'!B25 -> Hammanskraal Ext 4 | C12: ='Invoice — Region 2'!C25 -> 14 | E12: 46090 | F12: 46093 | G12: 46097 | H12: 46100 | I12: 46104 | J12: =COUNT(D12:I12) -> 5
A13: ='Invoice — Region 2'!B26 -> Hammanskraal portion 9 & 10 | C13: ='Invoice — Region 2'!C26 -> 160 | D13: 46086 | E13: 46090 | F13: 46093 | G13: 46097 | H13: 46100 | I13: 46104 | J13: =COUNT(D13:I13) -> 6
A14: ='Invoice — Region 2'!B27 -> Soshanguve X Buffer C | C14: ='Invoice — Region 2'!C27 -> 50 | E14: 46090 | F14: 46093 | G14: 46097 | H14: 46100 | I14: 46104 | J14: =COUNT(D14:I14) -> 5
A15: ='Invoice — Region 2'!B28 -> Soshanguve X Buffer D | C15: ='Invoice — Region 2'!C28 -> 60 | D15: 46086 | E15: 46090 | F15: 46093 | G15: 46097 | H15: 46100 | I15: 46104 | J15: =COUNT(D15:I15) -> 6
A16: ='Invoice — Region 2'!B29 -> Soshanguve X Buffer Civcon | C16: ='Invoice — Region 2'!C29 -> 10 | E16: 46090 | F16: 46093 | G16: 46097 | H16: 46100 | I16: 46104 | J16: =COUNT(D16:I16) -> 5
A17: ='Invoice — Region 2'!B30 -> Dali Mpofu | C17: ='Invoice — Region 2'!C30 -> 40 | D17: 46086 | E17: 46090 | F17: 46093 | G17: 46097 | H17: 46100 | I17: 46104 | J17: =COUNT(D17:I17) -> 6
A18: ='Invoice — Region 2'!B31 -> Stinkwater | C18: ='Invoice — Region 2'!C31 -> 3 | E18: 46090 | F18: 46093 | G18: 46097 | H18: 46100 | I18: 46104 | J18: =COUNT(D18:I18) -> 5
A19: ='Invoice — Region 2'!B32 -> Stinkwater Ext 10 | C19: ='Invoice — Region 2'!C32 -> 70 | E19: 46090 | F19: 46093 | G19: 46097 | H19: 46100 | I19: 46104 | J19: =COUNT(D19:I19) -> 5
A20: ='Invoice — Region 2'!B33 -> Chris Hani | C20: ='Invoice — Region 2'!C33 -> 80 | D20: 46086 | E20: 46090 | F20: 46093 | G20: 46097 | H20: 46100 | I20: 46104 | J20: =COUNT(D20:I20) -> 6
A21: ='Invoice — Region 2'!B34 -> Phomolong Phase 1 | C21: ='Invoice — Region 2'!C34 -> 59 | E21: 46090 | F21: 46093 | G21: 46097 | H21: 46100 | I21: 46104 | J21: =COUNT(D21:I21) -> 5
A22: ='Invoice — Region 2'!B35 -> Greenfield Ext 14 (Lefika Camp) | C22: ='Invoice — Region 2'!C35 -> 15 | E22: 46090 | F22: 46093 | G22: 46097 | H22: 46100 | I22: 46104 | J22: =COUNT(D22:I22) -> 5
A26: Service Provider Signature: | F26: City of Tshwane Official:
A28: 46107
A29: Date | F29: Date

Sheet Clearning Schedule
A1: Weekly Cleaning Schedule
A4: Informal Settlement Area | C4: No of Toilets | D4: Weekly Cleaning Dates
A5: Themba View Ext 1 | C5: 8 | D5: Monday & Thursday
A6: Marokolong | C6: 11 | D6: Monday & Thursday
A7: Hammanskraal Ext 4 | C7: 30 | D7: Monday & Thursday
A8: Hammanskraal portion 9 & 10 | C8: 160 | D8: Monday & Thursday
A9: Soshanguve X Buffer C | C9: 50 | D9: Monday & Thursday
A10: Soshanguve X Buffer D | C10: 60 | D10: Monday & Thursday
A11: Soshanguve X Buffer Civcon | C11: 10 | D11: Monday & Thursday
A12: Dali Mpofu | C12: 40 | D12: Monday & Thursday
A13: Stinkwater | C13: 3 | D13: Monday & Thursday
A14: Stinkwater Ext 10 | C14: 70 | D14: Monday & Thursday
A15: Chris Hani | C15: 80 | D15: Monday & Thursday
A16: Phomolong Phase 1 | C16: 59 | D16: Monday & Thursday
A17: Greenfield Ext 14 (Lefika Camp) | C17: 15 | D17: Monday & Thursday
A20: Service Provider Official: | C20: City of Tshwane Official:
A22: #VALUE!
A23: Signature | C23: Signature
A25: 46107
A26: Date | C26: Date

Sheet EPWP Employees
A1: SITHEMBE TRANSPORTATION & PROJECTS | D1: EPWP Employee List
A3: FULLNAME | B3: ID NUMBER | D3: LOCATION | E3: POSITION
A4: Phuti Kololo | B4: 9305225537087 | D4: Chris Hani | E4: Coordinator
A5: Angelina Nomsa Ndlela | B5: 6806201263088 | D5: Chris Hani | E5: Cleaner
A6: Sbongile Josephine Vilakazi | B6: 7509221121083 | D6: Chris Hani | E6: Cleaner
A7: Pop Johannes Sebaiwa | B7: 8202015595089 | D7: Chris Hani | E7: Cleaner
A8: Sebakiswe Florah Makala | B8: 8003051321087 | D8: Chris Hani | E8: Cleaner
A9: Tiny Johanna Pine | B9: 8311170776085 | D9: Chris Hani | E9: Cleaner
A10: Gomolemo Ndlovu | B10: 9503010642084 | D10: Chris Hani | E10: Cleaner
A11: Ntsako Kubai | B11: 9805131078084 | D11: Chris Hani | E11: Cleaner
A12: Dorcas Marutlolle | B12: 9809260260083 | D12: Chris Hani | E12: Cleaner
A13: Karabo Ramalepe | B13: 8306205458089 | D13: Dali Mpofu | E13: Coordinator
A14: Sindy Klein | B14: 7408140901081 | D14: Dali Mpofu | E14: Cleaner
A15: Matome Mahasha | B15: 7501016014086 | D15: Dali Mpofu | E15: Cleaner
... A28: Martha Tshabalala | B28: 7201190649084 | D28: Hammaskraal Portion 9 & 10 | E28: Cleaner
A29: Flora Shongwane | B29: '7311161001080 | D29: Hammaskraal Portion 9 & 10 | E29: Cleaner
A30: Stella Baloyi | B30: 8203060594084 | D30: Hammaskraal Portion 9 & 10 | E30: Cleaner
A31: Sibongile Mashiloane | B31: 8709101729083 | D31: Hammaskraal Portion 9 & 10 | E31: Cleaner
A32: Alphinah Sebatjane | B32: 8607161064088 | D32: Hammaskraal Portion 9 & 10 | E32: Coordinator
A33: Koketso Morudu | B33: 96090991239088 | D33: Hammaskraal Portion 9 & 10 | E33: Cleaner
A34: Patronell Paries | B34: 7311020432088 | D34: Hammaskraal Portion 9 & 10 | E34: Coordinator
A35: Martha Maluleke | B35: 9208251142089 | D35: Morokolong/ Marokolong | E35: Cleaner
A36: George Mlambo | B36: 8705245844085 | D36: Morokolong/ Marokolong | E36: Cleaner
A37: Mavis Ratlhagane | B37: 7304041326082 | D37: Phomolong (Phase 1) | E37: Cleaner
A38: Tsholofelo Selinah Mogoto | B38: 9703270988082 | D38: Phomolong (Phase 1) | E38: Cleaner
A39: Nono Pauline Moima | B39: 9111191057088 | D39: Phomolong (Phase 1) | E39: Cleaner
A40: Lindiwe Prudence Mahlangu | B40: 8107300402083 | D40: Phomolong (Phase 1) | E40: Cleaner
A41: Elsie Makganana Mabasu | B41: 8506131200089 | D41: Phomolong (Phase 1) | E41: Coordinator
... A63: VICTORIA GUMEDE | B63: 9212140363088 | D63: Stinkwater Ext 10 | E63: Cleaner
A65: Service Provider Official: | D65: City of Tshwane Official:
A66: #VALUE!
A67: Signature | D67: Signature
A68: 46107
A69: Date | D69: Date
