Workbook

Sheet Invoice - Region 2
A1: SITHEMBE TRANSPORTATION & PROJECTS | G1: Tax Invoice
A3: Tel: 012 880 3155 | Cell: 073 124 1535 | Fax: 086 603 7935 | E3: Tax Invoice No: | H3: STP-INV-26-0389
A4: Email: accounts@sithembe.co.za | info@sithembe.co.za | E4: Invoice Date: | H4: =TEXT(DATE(YEAR(TODAY()),MONTH(TODAY()),30),"dd mmmm yyyy") -> 30 July 2026
A5: VAToilet Number: 4070272101 | Vendor No: 101776 | E5: Service Period: | H5: 26 May 2026 To 30 June 2026
A6: Reg No: 2013/029173/07 | www.sithembe.co.za | E6: Region: | H6: Region 2
A7: Contract Ref: HS 02-2025/26
A9: BILL TO:
A10: City of Tshwane
A11: PO Box 6338
A12: Pretoria
A13: 0001
A15: VAT Number: 4000142267
A16: Tel: 012 358 3368
A18: # | B18: TOWNSHIP / INFORMAL SETTLEMENT | C18: RENTALS & RELOCATIONS | F18: SERVICE | H18: SUB TOTALS
B19: TOWNSHIP / INFORMAL SETTLEMENT | C19: Qty (Units) | D19: Days in Period | E19: Rental Amount R11.50 | F19: No of Services | G19: Service Amount R96.50
A20: 1 | B20: Themba View Ext 1 | C20: 8 | D20: =J7 -> 0 | E20: =IF(C20="","",C20*D20*11.5) -> 0 | F20: ='Service Notes'!N8 -> 10 | G20: =IF(C20="","",C20*F20*96.5) -> 7720 | H20: =IF(C20="","",E20+G20) -> 7720
A21: 3 | B21: Marokolong | C21: 11 | D21: =D20 -> 0 | E21: =IF(C21="","",C21*D21*11.5) -> 0 | F21: ='Service Notes'!N9 -> 10 | G21: =IF(C21="","",C21*F21*96.5) -> 10615 | H21: =IF(C21="","",E21+G21) -> 10615
A22: 4 | B22: Hammanskraal Ext 4 | C22: 30 | D22: =D21 -> 0 | E22: =IF(C22="","",C22*D22*11.5) -> 0 | F22: ='Service Notes'!N10 -> 10 | G22: =IF(C22="","",C22*F22*96.5) -> 28950 | H22: =IF(C22="","",E22+G22) -> 28950
A23: 6 | B23: Hammanskraal portion 9 & 10 | C23: 160 | D23: =D22 -> 0 | E23: =IF(C23="","",C23*D23*11.5) -> 0 | F23: ='Service Notes'!N11 -> 10 | G23: =IF(C23="","",C23*F23*96.5) -> 154400 | H23: =IF(C23="","",E23+G23) -> 154400
A24: 7 | B24: Soshanguve X Buffer C | C24: 50 | D24: =D23 -> 0 | E24: =IF(C24="","",C24*D24*11.5) -> 0 | F24: ='Service Notes'!N12 -> 10 | G24: =IF(C24="","",C24*F24*96.5) -> 48250 | H24: =IF(C24="","",E24+G24) -> 48250
A25: 8 | B25: Soshanguve X Buffer D | C25: 60 | D25: =D24 -> 0 | E25: =IF(C25="","",C25*D25*11.5) -> 0 | F25: ='Service Notes'!N13 -> 10 | G25: =IF(C25="","",C25*F25*96.5) -> 57900 | H25: =IF(C25="","",E25+G25) -> 57900
A26: 9 | B26: Soshanguve X Buffer Civcon | C26: 10 | D26: =D25 -> 0 | E26: =IF(C26="","",C26*D26*11.5) -> 0 | F26: ='Service Notes'!N14 -> 10 | G26: =IF(C26="","",C26*F26*96.5) -> 9650 | H26: =IF(C26="","",E26+G26) -> 9650
A27: 10 | B27: Dali Mpofu | C27: 40 | D27: =D26 -> 0 | E27: =IF(C27="","",C27*D27*11.5) -> 0 | F27: ='Service Notes'!N15 -> 10 | G27: =IF(C27="","",C27*F27*96.5) -> 38600 | H27: =IF(C27="","",E27+G27) -> 38600
A28: 11 | B28: Stinkwater | C28: 3 | D28: =D27 -> 0 | E28: =IF(C28="","",C28*D28*11.5) -> 0 | F28: ='Service Notes'!N16 -> 10 | G28: =IF(C28="","",C28*F28*96.5) -> 2895 | H28: =IF(C28="","",E28+G28) -> 2895
A29: 12 | B29: Stinkwater Ext 10 | C29: 70 | D29: =D28 -> 0 | E29: =IF(C29="","",C29*D29*11.5) -> 0 | F29: ='Service Notes'!N17 -> 10 | G29: =IF(C29="","",C29*F29*96.5) -> 67550 | H29: =IF(C29="","",E29+G29) -> 67550
A30: 13 | B30: Chris Hani | C30: 80 | D30: =D29 -> 0 | E30: =IF(C30="","",C30*D30*11.5) -> 0 | F30: ='Service Notes'!N18 -> 10 | G30: =IF(C30="","",C30*F30*96.5) -> 77200 | H30: =IF(C30="","",E30+G30) -> 77200
A31: 14 | B31: Phomolong Phase 1 | C31: 59 | D31: =D30 -> 0 | E31: =IF(C31="","",C31*D31*11.5) -> 0 | F31: ='Service Notes'!N19 -> 10 | G31: =IF(C31="","",C31*F31*96.5) -> 56935 | H31: =IF(C31="","",E31+G31) -> 56935
A32: 15 | B32: Greenfield Ext 14 (Lefika Camp) | C32: 15 | D32: =D31 -> 0 | E32: =IF(C32="","",C32*D32*11.5) -> 0 | F32: ='Service Notes'!N20 -> 10 | G32: =IF(C32="","",C32*F32*96.5) -> 14475 | H32: =IF(C32="","",E32+G32) -> 14475
E33: =IF(C33="","",C33*$H$12*$H$13) | G33: =IF(C33="","",C33*F33*$H$14) | H33: =IF(C33="","",E33+G33)
D34: =IF(C34="","",$H$12) | E34: =IF(C34="","",C34*$H$12*$H$13) | G34: =IF(C34="","",C34*F34*$H$14)
B36: Sub Totals | C36: =SUM(C20:C34) -> 596 | E36: =SUM(E20:E34) -> 0 | G36: =SUM(G20:G34) -> 575140 | H36: =SUM(E36,G36) -> 575140 | I36: =SUM(H20:H32) -> 575140
G37: VAT @ 15% | H37: =H36*15% -> 86271
A38: BANKING DETAILS | F38: Gross Total | H38: =H36+H37 -> 661411
A39: Account Holder: Sithembe Transportation and Projects (Pty) Ltd
A40: Bank: Nedbank Limited
A41: AccounToilet Number: 1323687157
A42: Branch Code: 198765
E43: City of Tshwane Official:
A46: Service Provider Signature: | E46: Signature:
A48: =H4 -> 30 July 2026
...

Sheet Service Notes
A1: SITHEMBE TRANSPORTATION & PROJECTS | K1: Service Notes - Pump & Clean
A3: City of Thswane
A4: Hiring and Servicing of chemical toilets
A5: HS 02-2025/26
A6: Service Notes (From 26 May 2026 To 30 June 2026)
A7: TOWNSHIP / INFORMAL SETTLEMENT | C7: Qty (Units) | D7: THURSDAY | E7: MONDAY | F7: THURSDAY | G7: MONDAY | H7: THURSDAY | I7: MONDAY | J7: THURSDAY | K7: MONDAY | L7: THURSDAY | M7: MONDAY | N7: No of Service
A8: ='Invoice - Region 2'!B20 -> Themba View Ext 1 | C8: ='Invoice - Region 2'!C20 -> 8 | D8: 46170 | E8: 46174 | F8: 46177 | G8: 46181 | H8: 46184 | I8: 46188 | J8: 46191 | K8: 46195 | L8: 46198 | M8: 46202 | N8: =COUNT(D8:M8) -> 10
A9: ='Invoice - Region 2'!B21 -> Marokolong | C9: ='Invoice - Region 2'!C21 -> 11 | D9: 46170 | E9: 46174 | F9: 46177 | G9: 46181 | H9: 46184 | I9: 46188 | J9: 46191 | K9: 46195 | L9: 46198 | M9: 46202 | N9: =COUNT(D9:M9) -> 10
A10: ='Invoice - Region 2'!B22 -> Hammanskraal Ext 4 | C10: ='Invoice - Region 2'!C22 -> 30 | D10: 46170 | E10: 46174 | F10: 46177 | G10: 46181 | H10: 46184 | I10: 46188 | J10: 46191 | K10: 46195 | L10: 46198 | M10: 46202 | N10: =COUNT(D10:M10) -> 10
A11: ='Invoice - Region 2'!B23 -> Hammanskraal portion 9 & 10 | C11: ='Invoice - Region 2'!C23 -> 160 | D11: 46170 | E11: 46174 | F11: 46177 | G11: 46181 | H11: 46184 | I11: 46188 | J11: 46191 | K11: 46195 | L11: 46198 | M11: 46202 | N11: =COUNT(D11:M11) -> 10
A12: ='Invoice - Region 2'!B24 -> Soshanguve X Buffer C | C12: ='Invoice - Region 2'!C24 -> 50 | D12: 46170 | E12: 46174 | F12: 46177 | G12: 46181 | H12: 46184 | I12: 46188 | J12: 46191 | K12: 46195 | L12: 46198 | M12: 46202 | N12: =COUNT(D12:M12) -> 10
A13: ='Invoice - Region 2'!B25 -> Soshanguve X Buffer D | C13: ='Invoice - Region 2'!C25 -> 60 | D13: 46170 | E13: 46174 | F13: 46177 | G13: 46181 | H13: 46184 | I13: 46188 | J13: 46191 | K13: 46195 | L13: 46198 | M13: 46202 | N13: =COUNT(D13:M13) -> 10
A14: ='Invoice - Region 2'!B26 -> Soshanguve X Buffer Civcon | C14: ='Invoice - Region 2'!C26 -> 10 | D14: 46170 | E14: 46174 | F14: 46177 | G14: 46181 | H14: 46184 | I14: 46188 | J14: 46191 | K14: 46195 | L14: 46198 | M14: 46202 | N14: =COUNT(D14:M14) -> 10
A15: ='Invoice - Region 2'!B27 -> Dali Mpofu | C15: ='Invoice - Region 2'!C27 -> 40 | D15: 46170 | E15: 46174 | F15: 46177 | G15: 46181 | H15: 46184 | I15: 46188 | J15: 46191 | K15: 46195 | L15: 46198 | M15: 46202 | N15: =COUNT(D15:M15) -> 10
A16: ='Invoice - Region 2'!B28 -> Stinkwater | C16: ='Invoice - Region 2'!C28 -> 3 | D16: 46170 | E16: 46174 | F16: 46177 | G16: 46181 | H16: 46184 | I16: 46188 | J16: 46191 | K16: 46195 | L16: 46198 | M16: 46202 | N16: =COUNT(D16:M16) -> 10
A17: ='Invoice - Region 2'!B29 -> Stinkwater Ext 10 | C17: ='Invoice - Region 2'!C29 -> 70 | D17: 46170 | E17: 46174 | F17: 46177 | G17: 46181 | H17: 46184 | I17: 46188 | J17: 46191 | K17: 46195 | L17: 46198 | M17: 46202 | N17: =COUNT(D17:M17) -> 10
A18: ='Invoice - Region 2'!B30 -> Chris Hani | C18: ='Invoice - Region 2'!C30 -> 80 | D18: 46170 | E18: 46174 | F18: 46177 | G18: 46181 | H18: 46184 | I18: 46188 | J18: 46191 | K18: 46195 | L18: 46198 | M18: 46202 | N18: =COUNT(D18:M18) -> 10
A19: ='Invoice - Region 2'!B31 -> Phomolong Phase 1 | C19: ='Invoice - Region 2'!C31 -> 59 | D19: 46170 | E19: 46174 | F19: 46177 | G19: 46181 | H19: 46184 | I19: 46188 | J19: 46191 | K19: 46195 | L19: 46198 | M19: 46202 | N19: =COUNT(D19:M19) -> 10
A20: ='Invoice - Region 2'!B32 -> Greenfield Ext 14 (Lefika Camp) | C20: ='Invoice - Region 2'!C32 -> 15 | D20: 46170 | E20: 46174 | F20: 46177 | G20: 46181 | H20: 46184 | I20: 46188 | J20: 46191 | K20: 46195 | L20: 46198 | M20: 46202 | N20: =COUNT(D20:M20) -> 10
A24: Service Provider Signature: | J24: City of Tshwane Official:
A26: ='Invoice - Region 2'!H4 -> 30 July 2026
A27: Date | J27: Date

Sheet Clearning Schedule
A1: Weekly Cleaning Schedule
A3: Informal Settlement Area | C3: No of Toilets | D3: Weekly Cleaning Dates
A4: Themba View Ext 1 | C4: 8 | D4: Monday & Thursday
A5: Marokolong | C5: 11 | D5: Monday & Thursday
A6: Hammanskraal Ext 4 | C6: 30 | D6: Monday & Thursday
A7: Hammanskraal portion 9 & 10 | C7: 160 | D7: Monday & Thursday
A8: Soshanguve X Buffer C | C8: 50 | D8: Monday & Thursday
A9: Soshanguve X Buffer D | C9: 60 | D9: Monday & Thursday
A10: Soshanguve X Buffer Civcon | C10: 10 | D10: Monday & Thursday
A11: Dali Mpofu | C11: 40 | D11: Monday & Thursday
A12: Stinkwater | C12: 3 | D12: Monday & Thursday
A13: Stinkwater Ext 10 | C13: 70 | D13: Monday & Thursday
A14: Chris Hani | C14: 80 | D14: Monday & Thursday
A15: Phomolong Phase 1 | C15: 59 | D15: Monday & Thursday
A16: Greenfield Ext 14 (Lefika Camp) | C16: 15 | D16: Monday & Thursday
A19: Service Provider Official: | C19: City of Tshwane Official:
A22: Signature | C22: Signature
A24: ='Invoice - Region 2'!H4 -> 30 July 2026
A25: Date | C25: Date

Sheet EPWP Employees
A1: SITHEMBE TRANSPORTATION & PROJECTS | D1: EPWP Employee List
A3: FULLNAME | B3: ID NUMBER | D3: LOCATION | E3: POSITION
A4: Phuti Kololo | B4: 9305225537087 | D4: Chris Hani | E4: Coordinator
A5: Angelina Nomsa Ndlela | B5: 6806201263088 | D5: Chris Hani | E5: Cleaner
A6: Sbongile Josephine Vilakazi | B6: 7509221121083 | D6: Chris Hani | E6: Cleaner
A7: Pop Johannes Sebaiwa | B7: 8202015595089 | D7: Chris Hani | E7: Cleaner
A8: Sebakiswe Florah Makala | B8: 8003051321087 | D8: Chris Hani | E8: Cleaner
A9: Tiny Johanna Pine | B9: 8311170776085 | D9: Chris Hani | E9: Cleaner
A10: Gomolemo Ndlovu | B10: 9503010642084 | D10: Chris Hani | E10: Cleaner
A11: Ntsako Kubai | B11: 9805131078084 | D11: Chris Hani | E11: Cleaner
A12: Dorcas Marutlolle | B12: 9809260260083 | D12: Chris Hani | E12: Cleaner
A13: Karabo Ramalepe | B13: 8306205458089 | D13: Dali Mpofu | E13: Coordinator
A14: Sindy Klein | B14: 7408140901081 | D14: Dali Mpofu | E14: Cleaner
A15: Matome Mahasha | B15: 7501016014086 | D15: Dali Mpofu | E15: Cleaner
... A28: Martha Tshabalala | B28: 7201190649084 | D28: Hammaskraal Portion 9 & 10 | E28: Cleaner
A29: Flora Shongwane | B29: '7311161001080 | D29: Hammaskraal Portion 9 & 10 | E29: Cleaner
A30: Stella Baloyi | B30: 8203060594084 | D30: Hammaskraal Portion 9 & 10 | E30: Cleaner
A31: Sibongile Mashiloane | B31: 8709101729083 | D31: Hammaskraal Portion 9 & 10 | E31: Cleaner
A32: Alphinah Sebatjane | B32: 8607161064088 | D32: Hammaskraal Portion 9 & 10 | E32: Coordinator
A33: Koketso Morudu | B33: 96090991239088 | D33: Hammaskraal Portion 9 & 10 | E33: Cleaner
A34: Patronell Paries | B34: 7311020432088 | D34: Hammaskraal Portion 9 & 10 | E34: Coordinator
A35: Martha Maluleke | B35: 9208251142089 | D35: Morokolong/ Marokolong | E35: Cleaner
A36: George Mlambo | B36: 8705245844085 | D36: Morokolong/ Marokolong | E36: Cleaner
A37: Mavis Ratlhagane | B37: 7304041326082 | D37: Phomolong (Phase 1) | E37: Cleaner
A38: Tsholofelo Selinah Mogoto | B38: 9703270988082 | D38: Phomolong (Phase 1) | E38: Cleaner
A39: Nono Pauline Moima | B39: 9111191057088 | D39: Phomolong (Phase 1) | E39: Cleaner
A40: Lindiwe Prudence Mahlangu | B40: 8107300402083 | D40: Phomolong (Phase 1) | E40: Cleaner
A41: Elsie Makganana Mabasu | B41: 8506131200089 | D41: Phomolong (Phase 1) | E41: Coordinator
... A63: VICTORIA GUMEDE | B63: 9212140363088 | D63: Stinkwater Ext 10 | E63: Cleaner
A64: JULY CHABANGU | B64: 0107015422085 | D64: REGION 2 | E64: DRIVER
A65: SIZWE MAHLANGU | B65: 8810195855089 | D65: REGION 2 | E65: DRIVER
A67: Service Provider Official: | D67: City of Tshwane Official:
A69: Signature | D69: Signature
A70: ='Invoice - Region 2'!H4 -> 30 July 2026
A71: Date | D71: Date
