Workbook

Sheet Invoice — Region 2
A1: SITHEMBE TRANSPORTATION & PROJECTS | J1: Tax Invoice
A3: Tel: 012 880 3155 | Cell: 073 124 1535 | Fax: 086 603 7935 | H3: Tax Invoice No: | K3: STP/INV/26/0353
A4: Email: accounts@sithembe.co.za | info@sithembe.co.za | H4: Invoice Date: | K4: =TEXT(DATE(YEAR(TODAY()),MONTH(TODAY()),26),"dd mmmm yyyy") -> 26 May 2026
A5: VAT No: 4000142267 | Vendor No: 101776 | H5: Service Period: | K5: =TEXT(K4,"mmmm YY") & " (" & TEXT(DATE(YEAR(K4),MONTH(K4),1),"dd mmm") & " - " & TEXT(DATE(YEAR(K4),MONTH(K4),25),"dd mmm") & ")" -> May 26 (01 May - 25 May)
A6: Reg No: 2013/029173/07 | www.sithembe.co.za | H6: Days in Period: | K6: =DATE(YEAR(K4),MONTH(K4),25) - DATE(YEAR(K4),MONTH(K4),1) + 1 -> 25
A7: Contract Ref: HHS 02-2021/22 | H7: PO Number:
A10: BILL TO:
A11: City of Tshwane Metropolitan Municipality | H11: Region: | K11: Region 2
A12: Human Settlements & Operations and Coordination Deptment | H12: Hire Rate (excl VAT): | K12: 11.5
A13: Isivuno House, 330 Madiba Street | H13: Service Rate (excl VAT): | K13: 96.5
A14: PO Box 440, Pretoria, 0001 | H14: Relocation Rate (excl VAT) | K14: 7
H15: Project Manager | K15: Ms. Thokozile Maluka
A19: # | B19: TOWNSHIP / INFORMAL SETTLEMENT | C19: Ward No | D19: RENTALS & RELOCATIONS | I19: SERVICE | K19: SUB TOTALS
B20: TOWNSHIP / INFORMAL SETTLEMENT | D20: Qty (Units) | E20: Toilet Relocation | F20: Relocation Amount (excl VAT) | G20: Days in Period | H20: Rental Amount (excl VAT) | I20: No of Services | J20: Service Amount (excl VAT)
A21: 1 | B21: Themba View | C21: 8 | D21: 8 | E21: 0 | F21: =IF(E21="","",E21*$K$14) -> 0 | G21: =IF(D21="","",$K$6) -> 25 | H21: =IF(D21="","",D21*$K$12*$K$6) -> 2300 | I21: ='Service Notes'!AH13 -> 6 | J21: =IF(D21="","",D21*I21*$K$13) -> 4632 | K21: =IF(D21="","",F21+H21+J21) -> 6932
A22: 2 | B22: Marokolong | C22: 73 | D22: 11 | E22: 0 | F22: =IF(E22="","",E22*$K$14) -> 0 | G22: =IF(D22="","",$K$6) -> 25 | H22: =IF(D22="","",D22*$K$12*$K$6) -> 3162.5 | I22: ='Service Notes'!AH14 -> 7 | J22: =IF(D22="","",D22*I22*$K$13) -> 7430.5 | K22: =IF(D22="","",F22+H22+J22) -> 10593
A23: 3 | B23: Hammanskraal Ext 4 | C23: 49 | D23: 30 | E23: 0 | F23: =IF(E23="","",E23*$K$14) -> 0 | G23: =IF(D23="","",$K$6) -> 25 | H23: =IF(D23="","",D23*$K$12*$K$6) -> 8625 | I23: ='Service Notes'!AH15 -> 6 | J23: =IF(D23="","",D23*I23*$K$13) -> 17370 | K23: =IF(D23="","",F23+H23+J23) -> 25995
A24: 4 | B24: Hammanskraal portion 9 & 10 | C24: 49 | D24: 160 | E24: 0 | F24: =IF(E24="","",E24*$K$14) -> 0 | G24: =IF(D24="","",$K$6) -> 25 | H24: =IF(D24="","",D24*$K$12*$K$6) -> 46000 | I24: ='Service Notes'!AH16 -> 6 | J24: =IF(D24="","",D24*I24*$K$13) -> 92640 | K24: =IF(D24="","",F24+H24+J24) -> 138640
A25: 5 | B25: Soshanguve X Buffer C | C25: 95 | D25: 50 | E25: 0 | F25: =IF(E25="","",E25*$K$14) -> 0 | G25: =IF(D25="","",$K$6) -> 25 | H25: =IF(D25="","",D25*$K$12*$K$6) -> 14375 | I25: ='Service Notes'!AH17 -> 6 | J25: =IF(D25="","",D25*I25*$K$13) -> 28950 | K25: =IF(D25="","",F25+H25+J25) -> 43325
A26: 6 | B26: Soshanguve X Buffer D | C26: 95 | D26: 60 | E26: 0 | F26: =IF(E26="","",E26*$K$14) -> 0 | G26: =IF(D26="","",$K$6) -> 25 | H26: =IF(D26="","",D26*$K$12*$K$6) -> 17250 | I26: ='Service Notes'!AH18 -> 8 | J26: =IF(D26="","",D26*I26*$K$13) -> 46320 | K26: =IF(D26="","",F26+H26+J26) -> 63570
A27: 7 | B27: Soshanguve X Buffer Civcon | C27: 95 | D27: 10 | E27: 0 | F27: =IF(E27="","",E27*$K$14) -> 0 | G27: =IF(D27="","",$K$6) -> 25 | H27: =IF(D27="","",D27*$K$12*$K$6) -> 2875 | I27: ='Service Notes'!AH19 -> 7 | J27: =IF(D27="","",D27*I27*$K$13) -> 6755 | K27: =IF(D27="","",F27+H27+J27) -> 9630
A28: 8 | B28: Dali Mpofu | C28: 95 | D28: 40 | E28: 0 | F28: =IF(E28="","",E28*$K$14) -> 0 | G28: =IF(D28="","",$K$6) -> 25 | H28: =IF(D28="","",D28*$K$12*$K$6) -> 11500 | I28: ='Service Notes'!AH20 -> 7 | J28: =IF(D28="","",D28*I28*$K$13) -> 27020 | K28: =IF(D28="","",F28+H28+J28) -> 38520
A29: 9 | B29: Stinkwater | C29: 95 | D29: 3 | E29: 0 | F29: =IF(E29="","",E29*$K$14) -> 0 | G29: =IF(D29="","",$K$6) -> 25 | H29: =IF(D29="","",D29*$K$12*$K$6) -> 862.5 | I29: ='Service Notes'!AH21 -> 7 | J29: =IF(D29="","",D29*I29*$K$13) -> 2026.5 | K29: =IF(D29="","",F29+H29+J29) -> 2889
A30: 10 | B30: Stinkwater Ext 10 | C30: 13 | D30: 70 | E30: 0 | F30: =IF(E30="","",E30*$K$14) -> 0 | G30: =IF(D30="","",$K$6) -> 25 | H30: =IF(D30="","",D30*$K$12*$K$6) -> 20125 | I30: ='Service Notes'!AH22 -> 8 | J30: =IF(D30="","",D30*I30*$K$13) -> 54040 | K30: =IF(D30="","",F30+H30+J30) -> 74165
A31: 11 | B31: Chris Hani | C31: 75 | D31: 80 | E31: 0 | F31: =IF(E31="","",E31*$K$14) -> 0 | G31: =IF(D31="","",$K$6) -> 25 | H31: =IF(D31="","",D31*$K$12*$K$6) -> 23000 | I31: ='Service Notes'!AH23 -> 7 | J31: =IF(D31="","",D31*I31*$K$13) -> 54040 | K31: =IF(D31="","",F31+H31+J31) -> 77040
A32: 12 | B32: Phomolong Phase 1 | C32: 8 | D32: 59 | E32: 0 | F32: =IF(E32="","",E32*$K$14) -> 0 | G32: =IF(D32="","",$K$6) -> 25 | H32: =IF(D32="","",D32*$K$12*$K$6) -> 16962.5 | I32: ='Service Notes'!AH24 -> 7 | J32: =IF(D32="","",D32*I32*$K$13) -> 39854.5 | K32: =IF(D32="","",F32+H32+J32) -> 56817
A33: 13 | B33: Greenfield Ext 14 (Lefika) | C33: 49 | D33: 15 | E33: 0 | F33: =IF(E33="","",E33*$K$14) -> 0 | G33: =IF(D33="","",$K$6) -> 25 | H33: =IF(D33="","",D33*$K$12*$K$6) -> 4312.5 | I33: ='Service Notes'!AH25 -> 7 | J33: =IF(D33="","",D33*I33*$K$13) -> 10132.5 | K33: =IF(D33="","",F33+H33+J33) -> 14445
A34: 14 | G34: =IF(D34="","",$K$13) | H34: =IF(D34="","",D34*$K$13*$K$14) | J34: =IF(D34="","",D34*I34*$K$15) | K34: =IF(D34="","",H34+J34)
A35: 15 | G35: =IF(D35="","",$K$13) | H35: =IF(D35="","",D35*$K$13*$K$14) | J35: =IF(D35="","",D35*I35*$K$15)
B37: Sub Totals | D37: =SUM(D21:D35) -> 596 | E37: =SUM(E21:E35) -> 0 | F37: =SUM(F21:F35) -> 0 | H37: =SUM(H21:H35) -> 171350 | J37: =SUM(J21:J35) -> 391211 | K37: =SUM(F37,H37,J37) -> 562561 | L37: =SUM(K21:K33) -> 562561
J38: VAT @ 15% | K38: =K37*15% -> 84384.15
A39: BANKING DETAILS | H39: Gross Total | K39: =K37+K38 -> 646945.15
A40: Account Holder: Sithembe Transportation and Projects (Pty) Ltd
A41: Bank: Nedbank Limited
A42: Account No: 1323687157
A43: Branch Code: 198765
H44: City of Tshwane Official:
A47: Service Provider Signature: | H47: Signature:
A49: =K4 -> 26 May 2026
A50: Date: | H50: Date:

Sheet Service Notes
A1: SITHEMBE TRANSPORTATION & PROJECTS | P1: Service Notes
A3: Tel: 012 880 3155 | Cell: 073 124 1535 | Fax: 086 603 7935 | Z3: Tax Invoice No: | AC3: ='Invoice — Region 2'!K3 -> STP/INV/26/0353
A4: Email: accounts@sithembe.co.za | info@sithembe.co.za | Z4: Invoice Date: | AC4: ='Invoice — Region 2'!K4 -> 26 May 2026
A5: VAT No: 4000142267 | Vendor No: 101776 | Z5: Service Period: | AC5: ='Invoice — Region 2'!K5 -> May 26 (01 May - 25 May)
A6: Reg No: 2013/029173/07 | www.sithembe.co.za | Z6: Days in Period: | AC6: ='Invoice — Region 2'!K6 -> 25
A7: Contract Ref: HHS 02-2021/22 | Z7: PO Number: | AC7: =IF('Invoice — Region 2'!AA7="","",'Invoice — Region 2'!AA7)
A8: Project Manager: Ms. Thokozile Maluka | Z8: Region: | AC8: ='Invoice — Region 2'!K11 -> Region 2
A11: LOCATION | AH11: TOTAL
A12: TOWNSHIP / INFORMAL SETTLEMENT | C12: 46082 | D12: 46083 | E12: 46084 | F12: 46085 | G12: 46086 | H12: 46087 | I12: 46088 | J12: 46089 | K12: 46090 | L12: 46091 | M12: 46092 | N12: 46093 | O12: 46094 | P12: 46095 | Q12: 46096 | R12: 46097 | S12: 46098 | T12: 46099 | U12: 46100 | V12: 46101 | W12: 46102 | X12: 46103 | Y12: 46104 | Z12: 46105 | AA12: 46106 | AB12: 46107 | AC12: 46108 | AD12: 46109 | AE12: 46110 | AF12: 46111 | AG12: 46112
A13: ='Invoice — Region 2'!B21 -> Themba View | C13: FALSE | D13: FALSE | E13: FALSE | F13: TRUE | G13: FALSE | H13: FALSE | I13: FALSE | J13: FALSE | K13: TRUE | L13: FALSE | M13: TRUE | N13: FALSE | O13: FALSE | P13: FALSE | Q13: FALSE | R13: TRUE | S13: FALSE | T13: FALSE | U13: FALSE | V13: TRUE | W13: FALSE | X13: FALSE | Y13: FALSE | Z13: TRUE | AA13: FALSE | AB13: FALSE | AC13: FALSE | AD13: FALSE | AE13: FALSE | AF13: FALSE | AG13: FALSE | AH13: =COUNTIF(C13:AG13,TRUE) -> 6
A14: ='Invoice — Region 2'!B22 -> Marokolong | C14: FALSE | D14: FALSE | E14: FALSE | F14: TRUE | G14: FALSE | H14: FALSE | I14: FALSE | J14: FALSE | K14: TRUE | L14: FALSE | M14: FALSE | N14: TRUE | O14: FALSE | P14: FALSE | Q14: FALSE | R14: FALSE | S14: TRUE | T14: FALSE | U14: FALSE | V14: TRUE | W14: FALSE | X14: FALSE | Y14: FALSE | Z14: TRUE | AA14: TRUE | AB14: FALSE | AC14: FALSE | AD14: FALSE | AE14: FALSE | AF14: FALSE | AG14: FALSE | AH14: =COUNTIF(C14:AG14,TRUE) -> 7
A15: ='Invoice — Region 2'!B23 -> Hammanskraal Ext 4 | C15: FALSE | D15: FALSE | E15: FALSE | F15: TRUE | G15: FALSE | H15: FALSE | I15: FALSE | J15: FALSE | K15: TRUE | L15: FALSE | M15: FALSE | N15: FALSE | O15: TRUE | P15: FALSE | Q15: FALSE | R15: TRUE | S15: FALSE | T15: FALSE | U15: TRUE | V15: FALSE | W15: FALSE | X15: FALSE | Y15: FALSE | Z15: TRUE | AA15: FALSE | AB15: FALSE | AC15: FALSE | AD15: FALSE | AE15: FALSE | AF15: FALSE | AG15: FALSE | AH15: =COUNTIF(C15:AG15,TRUE) -> 6
A16: ='Invoice — Region 2'!B24 -> Hammanskraal portion 9 & 10 | C16: FALSE | D16: FALSE | E16: FALSE | F16: TRUE | G16: FALSE | H16: TRUE | I16: FALSE | J16: FALSE | K16: FALSE | L16: TRUE | M16: FALSE | N16: FALSE | O16: FALSE | P16: FALSE | Q16: FALSE | R16: TRUE | S16: FALSE | T16: FALSE | U16: TRUE | V16: FALSE | W16: FALSE | X16: FALSE | Y16: TRUE | Z16: FALSE | AA16: FALSE | AB16: FALSE | AC16: FALSE | AD16: FALSE | AE16: FALSE | AF16: FALSE | AG16: FALSE | AH16: =COUNTIF(C16:AG16,TRUE) -> 6
A17: ='Invoice — Region 2'!B25 -> Soshanguve X Buffer C | C17: FALSE | D17: FALSE | E17: FALSE | F17: FALSE | G17: TRUE | H17: FALSE | I17: FALSE | J17: FALSE | K17: TRUE | L17: FALSE | M17: FALSE | N17: FALSE | O17: FALSE | P17: TRUE | Q17: FALSE | R17: TRUE | S17: FALSE | T17: FALSE | U17: TRUE | V17: FALSE | W17: FALSE | X17: FALSE | Y17: TRUE | Z17: FALSE | AA17: FALSE | AB17: FALSE | AC17: FALSE | AD17: FALSE | AE17: FALSE | AF17: FALSE | AG17: FALSE | AH17: =COUNTIF(C17:AG17,TRUE) -> 6
A18: ='Invoice — Region 2'!B26 -> Soshanguve X Buffer D | C18: FALSE | D18: FALSE | E18: FALSE | F18: TRUE | G18: FALSE | H18: TRUE | I18: FALSE | J18: FALSE | K18: TRUE | L18: FALSE | M18: TRUE | N18: FALSE | O18: FALSE | P18: TRUE | Q18: FALSE | R18: TRUE | S18: FALSE | T18: FALSE | U18: TRUE | V18: FALSE | W18: FALSE | X18: FALSE | Y18: FALSE | Z18: FALSE | AA18: TRUE | AB18: FALSE | AC18: FALSE | AD18: FALSE | AE18: FALSE | AF18: FALSE | AG18: FALSE | AH18: =COUNTIF(C18:AG18,TRUE) -> 8
A19: ='Invoice — Region 2'!B27 -> Soshanguve X Buffer Civcon | C19: FALSE | D19: FALSE | E19: FALSE | F19: TRUE | G19: FALSE | H19: TRUE | I19: FALSE | J19: FALSE | K19: TRUE | L19: FALSE | M19: FALSE | N19: FALSE | O19: FALSE | P19: TRUE | Q19: FALSE | R19: FALSE | S19: TRUE | T19: FALSE | U19: TRUE | V19: FALSE | W19: FALSE | X19: FALSE | Y19: TRUE | Z19: FALSE | AA19: FALSE | AB19: FALSE | AC19: FALSE | AD19: FALSE | AE19: FALSE | AF19: FALSE | AG19: FALSE | AH19: =COUNTIF(C19:AG19,TRUE) -> 7
A20: ='Invoice — Region 2'!B28 -> Dali Mpofu | C20: FALSE | D20: FALSE | E20: FALSE | F20: FALSE | G20: TRUE | H20: FALSE | I20: FALSE | J20: FALSE | K20: TRUE | L20: FALSE | M20: FALSE | N20: TRUE | O20: FALSE | P20: FALSE | Q20: FALSE | R20: TRUE | S20: FALSE | T20: FALSE | U20: TRUE | V20: FALSE | W20: FALSE | X20: FALSE | Y20: TRUE | Z20: FALSE | AA20: TRUE | AB20: FALSE | AC20: FALSE | AD20: FALSE | AE20: FALSE | AF20: FALSE | AG20: FALSE | AH20: =COUNTIF(C20:AG20,TRUE) -> 7
A21: ='Invoice — Region 2'!B29 -> Stinkwater | C21: FALSE | D21: FALSE | E21: FALSE | F21: TRUE | G21: FALSE | H21: TRUE | I21: FALSE | J21: FALSE | K21: TRUE | L21: TRUE | M21: FALSE | N21: FALSE | O21: FALSE | P21: FALSE | Q21: FALSE | R21: TRUE | S21: FALSE | T21: TRUE | U21: FALSE | V21: FALSE | W21: FALSE | X21: FALSE | Y21: TRUE | Z21: FALSE | AA21: FALSE | AB21: FALSE | AC21: FALSE | AD21: FALSE | AE21: FALSE | AF21: FALSE | AG21: FALSE | AH21: =COUNTIF(C21:AG21,TRUE) -> 7
A22: ='Invoice — Region 2'!B30 -> Stinkwater Ext 10 | C22: FALSE | D22: FALSE | E22: FALSE | F22: TRUE | G22: FALSE | H22: FALSE | I22: TRUE | J22: FALSE | K22: FALSE | L22: TRUE | M22: FALSE | N22: TRUE | O22: TRUE | P22: FALSE | Q22: FALSE | R22: FALSE | S22: TRUE | T22: FALSE | U22: FALSE | V22: TRUE | W22: FALSE | X22: FALSE | Y22: FALSE | Z22: TRUE | AA22: FALSE | AB22: FALSE | AC22: FALSE | AD22: FALSE | AE22: FALSE | AF22: FALSE | AG22: FALSE | AH22: =COUNTIF(C22:AG22,TRUE) -> 8
A23: ='Invoice — Region 2'!B31 -> Chris Hani | C23: FALSE | D23: FALSE | E23: FALSE | F23: FALSE | G23: TRUE | H23: FALSE | I23: FALSE | J23: FALSE | K23: TRUE | L23: FALSE | M23: FALSE | N23: FALSE | O23: TRUE | P23: FALSE | Q23: FALSE | R23: TRUE | S23: FALSE | T23: TRUE | U23: FALSE | V23: FALSE | W23: FALSE | X23: FALSE | Y23: TRUE | Z23: FALSE | AA23: TRUE | AB23: FALSE | AC23: FALSE | AD23: FALSE | AE23: FALSE | AF23: FALSE | AG23: FALSE | AH23: =COUNTIF(C23:AG23,TRUE) -> 7
A24: ='Invoice — Region 2'!B32 -> Phomolong Phase 1 | C24: FALSE | D24: FALSE | E24: FALSE | F24: FALSE | G24: TRUE | H24: FALSE | I24: FALSE | J24: TRUE | K24: FALSE | L24: FALSE | M24: TRUE | N24: FALSE | O24: TRUE | P24: FALSE | Q24: FALSE | R24: FALSE | S24: TRUE | T24: FALSE | U24: FALSE | V24: TRUE | W24: FALSE | X24: FALSE | Y24: FALSE | Z24: FALSE | AA24: TRUE | AB24: FALSE | AC24: FALSE | AD24: FALSE | AE24: FALSE | AF24: FALSE | AG24: FALSE | AH24: =COUNTIF(C24:AG24,TRUE) -> 7
A25: ='Invoice — Region 2'!B33 -> Greenfield Ext 14 (Lefika) | C25: FALSE | D25: FALSE | E25: TRUE | F25: FALSE | G25: FALSE | H25: TRUE | I25: FALSE | J25: FALSE | K25: FALSE | L25: TRUE | M25: FALSE | N25: TRUE | O25: FALSE | P25: FALSE | Q25: FALSE | R25: TRUE | S25: FALSE | T25: FALSE | U25: FALSE | V25: TRUE | W25: FALSE | X25: FALSE | Y25: FALSE | Z25: TRUE | AA25: FALSE | AB25: FALSE | AC25: FALSE | AD25: FALSE | AE25: FALSE | AF25: FALSE | AG25: FALSE | AH25: =COUNTIF(C25:AG25,TRUE) -> 7
Q38: City of Tshwane Official:
A41: Service Provider Signature: | Q41: Signature:
A43: =R4 -> 0
A44: Date: | Q44: Date:

Sheet Attendance Register
A1: SITHEMBE TRANSPORTATION & PROJECTS | G1: Attendance Register
A3: Tel: 012 880 3155 | Cell: 073 124 1535 | Fax: 086 603 7935 | H3: Tax Invoice No: | I3: ='Invoice — Region 2'!K3 -> STP/INV/26/0353
A4: Email: accounts@sithembe.co.za | info@sithembe.co.za | H4: Invoice Date: | I4: ='Invoice — Region 2'!K4 -> 26 May 2026
A5: VAT No: 4000142267 | Vendor No: 101776 | H5: Service Period: | I5: ='Invoice — Region 2'!K5 -> May 26 (01 May - 25 May)
A6: Reg No: 2013/029173/07 | www.sithembe.co.za | H6: Days in Period: | I6: =IF(I4="","",I4-DATE(YEAR(I4),MONTH(I4)-1,26)) -> 30
A7: Contract Ref: HHS 02-2021/22 | H7: PO Number: | I7: =IF('Invoice — Region 2'!K7="","",'Invoice — Region 2'!K7)
A8: Project Manager: Ms. Thokozile Maluka | H8: Region: | I8: ='Invoice — Region 2'!K11 -> Region 2
A10: ='EPWP Employees'!A10 -> FULLNAME | B10: ='EPWP Employees'!B10 -> ID NUMBER | C10: 1 | D10: 2 | E10: 3 | F10: 4 | G10: 5 | H10: 6 | I10: 7 | J10: 8 | K10: 9 | L10: TOTAL
C11: ='Service Notes'!C12 -> 46082 | D11: ='Service Notes'!M12 -> 46092 | E11: ='Service Notes'!N12 -> 46093 | F11: ='Service Notes'!O12 -> 46094 | G11: ='Service Notes'!P12 -> 46095 | H11: ='Service Notes'!Q12 -> 46096 | I11: ='Service Notes'!R12 -> 46097 | J11: ='Service Notes'!S12 -> 46098 | K11: ='Service Notes'!T12 -> 46099
A12: =IF('EPWP Employees'!A11="","",'EPWP Employees'!A11) -> Phuti Kololo | B12: =IF('EPWP Employees'!B11="","",'EPWP Employees'!B11) -> 9305225537087 | C12: FALSE | D12: FALSE | E12: FALSE | F12: FALSE | G12: FALSE | H12: FALSE | I12: FALSE | J12: FALSE | K12: FALSE | L12: =COUNTIF(C12:K12,TRUE) -> 0
A13: =IF('EPWP Employees'!A12="","",'EPWP Employees'!A12) -> Angelina Nomsa Ndlela | B13: =IF('EPWP Employees'!B12="","",'EPWP Employees'!B12) -> 6806201263088 | C13: FALSE | D13: FALSE | E13: FALSE | F13: FALSE | G13: FALSE | H13: FALSE | I13: FALSE | J13: FALSE | K13: FALSE | L13: =COUNTIF(C13:K13,TRUE) -> 0
A14: =IF('EPWP Employees'!A13="","",'EPWP Employees'!A13) -> Sbongile Josephine Vilakazi | B14: =IF('EPWP Employees'!B13="","",'EPWP Employees'!B13) -> 7509221121083 | C14: FALSE | D14: FALSE | E14: FALSE | F14: FALSE | G14: FALSE | H14: FALSE | I14: FALSE | J14: FALSE | K14: FALSE | L14: =COUNTIF(C14:K14,TRUE) -> 0
A15: =IF('EPWP Employees'!A14="","",'EPWP Employees'!A14) -> Pop Johannes Sebaiwa | B15: =IF('EPWP Employees'!B14="","",'EPWP Employees'!B14) -> 8202015595089 | C15: FALSE | D15: FALSE | E15: FALSE | F15: FALSE | G15: FALSE | H15: FALSE | I15: FALSE | J15: FALSE | K15: FALSE | L15: =COUNTIF(C15:K15,TRUE) -> 0
A16: =IF('EPWP Employees'!A15="","",'EPWP Employees'!A15) -> Sebakiswe Florah Makala | B16: =IF('EPWP Employees'!B15="","",'EPWP Employees'!B15) -> 8003051321087 | C16: FALSE | D16: FALSE | E16: FALSE | F16: FALSE | G16: FALSE | H16: FALSE | I16: FALSE | J16: FALSE | K16: FALSE | L16: =COUNTIF(C16:K16,TRUE) -> 0
A17: =IF('EPWP Employees'!A16="","",'EPWP Employees'!A16) -> Tiny Johanna Pine | B17: =IF('EPWP Employees'!B16="","",'EPWP Employees'!B16) -> 8311170776085 | C17: FALSE | D17: FALSE | E17: FALSE | F17: FALSE | G17: FALSE | H17: FALSE | I17: FALSE | J17: FALSE | K17: FALSE | L17: =COUNTIF(C17:K17,TRUE) -> 0
A18: =IF('EPWP Employees'!A17="","",'EPWP Employees'!A17) -> Gomolemo Ndlovu | B18: =IF('EPWP Employees'!B17="","",'EPWP Employees'!B17) -> 9503010642084 | C18: FALSE | D18: FALSE | E18: FALSE | F18: FALSE | G18: FALSE | H18: FALSE | I18: FALSE | J18: FALSE | K18: FALSE | L18: =COUNTIF(C18:K18,TRUE) -> 0
A19: =IF('EPWP Employees'!A18="","",'EPWP Employees'!A18) -> Ntsako Kubai | B19: =IF('EPWP Employees'!B18="","",'EPWP Employees'!B18) -> 9805131078084 | C19: FALSE | D19: FALSE | E19: FALSE | F19: FALSE | G19: FALSE | H19: FALSE | I19: FALSE | J19: FALSE | K19: FALSE | L19: =COUNTIF(C19:K19,TRUE) -> 0
A20: =IF('EPWP Employees'!A19="","",'EPWP Employees'!A19) -> Dorcas Marutlolle | B20: =IF('EPWP Employees'!B19="","",'EPWP Employees'!B19) -> 9809260260083 | C20: FALSE | D20: FALSE | E20: FALSE | F20: FALSE | G20: FALSE | H20: FALSE | I20: FALSE | J20: FALSE | K20: FALSE | L20: =COUNTIF(C20:K20,TRUE) -> 0
A21: =IF('EPWP Employees'!A20="","",'EPWP Employees'!A20) -> Rebecca Violet Kubeka | B21: =IF('EPWP Employees'!B20="","",'EPWP Employees'!B20) -> 7406040339089 | C21: FALSE | D21: FALSE | E21: FALSE | F21: FALSE | G21: FALSE | H21: FALSE | I21: FALSE | J21: FALSE | K21: FALSE | L21: =COUNTIF(C21:K21,TRUE) -> 0
A22: =IF('EPWP Employees'!A21="","",'EPWP Employees'!A21) -> Olivia Kateko Khoza | B22: =IF('EPWP Employees'!B21="","",'EPWP Employees'!B21) -> 8606060763089 | C22: FALSE | D22: FALSE | E22: FALSE | F22: FALSE | G22: FALSE | H22: FALSE | I22: FALSE | J22: FALSE | K22: FALSE | L22: =COUNTIF(C22:K22,TRUE) -> 0
A23: =IF('EPWP Employees'!A22="","",'EPWP Employees'!A22) -> Lepatla Goodwill Ngoetjana | B23: =IF('EPWP Employees'!B22="","",'EPWP Employees'!B22) -> 8212166424088 | C23: FALSE | D23: FALSE | E23: FALSE | F23: FALSE | G23: FALSE | H23: FALSE | I23: FALSE | J23: FALSE | K23: FALSE | L23: =COUNTIF(C23:K23,TRUE) -> 0
... A56: =IF('EPWP Employees'!A55="","",'EPWP Employees'!A55) -> Sibongile Mashiloane | B56: =IF('EPWP Employees'!B55="","",'EPWP Employees'!B55) -> 8709101729083 | C56: FALSE | D56: FALSE | E56: FALSE | F56: FALSE | G56: FALSE | H56: FALSE | I56: FALSE | J56: FALSE | K56: FALSE | L56: =COUNTIF(C56:K56,TRUE) -> 0
A61: Service Provider Signature:
A63: =I4 -> 26 May 2026
A64: Date:

Sheet EPWP Employees
A1: SITHEMBE TRANSPORTATION & PROJECTS | E1: EPWP Employee List
A3: Tel: 012 880 3155 | Cell: 073 124 1535 | Fax: 086 603 7935
A4: Email: accounts@sithembe.co.za | info@sithembe.co.za
A5: VAT No: 4000142267 | Vendor No: 101776
A6: Reg No: 2013/029173/07 | www.sithembe.co.za
A7: Contract Ref: HHS 02-2021/22
A8: Project Manager: Ms. Thokozile Maluka
A10: FULLNAME | B10: ID NUMBER | C10: LOCATION | D10: POSITION
A11: Phuti Kololo | B11: 9305225537087 | C11: Chris Hani | D11: Coordinator
A12: Angelina Nomsa Ndlela | B12: 6806201263088 | C12: Chris Hani | D12: Cleaner
A13: Sbongile Josephine Vilakazi | B13: 7509221121083 | C13: Chris Hani | D13: Cleaner
A14: Pop Johannes Sebaiwa | B14: 8202015595089 | C14: Chris Hani | D14: Cleaner
A15: Sebakiswe Florah Makala | B15: 8003051321087 | C15: Chris Hani | D15: Cleaner
A16: Tiny Johanna Pine | B16: 8311170776085 | C16: Chris Hani | D16: Cleaner
A17: Gomolemo Ndlovu | B17: 9503010642084 | C17: Chris Hani | D17: Cleaner
A18: Ntsako Kubai | B18: 9805131078084 | C18: Chris Hani | D18: Cleaner
A19: Dorcas Marutlolle | B19: 9809260260083 | C19: Chris Hani | D19: Cleaner
A20: Rebecca Violet Kubeka | B20: 7406040339089 | C20: Soshanguve X - Buffer D | D20: Coordinator
A21: Olivia Kateko Khoza | B21: 8606060763089 | C21: Soshanguve X - Buffer D | D21: Cleaner
... A69: VICTORIA GUMEDE | B69: 9212140363088 | C69: Stinkwater Ext 10 | D69: Cleaner
A70: SIZWE MAHLANGU | D70: Driver
A71: JULY | D71: Driver
A72: URSULA KGOPA | B72: 8304120840085 | C72: Dali Mpofu | D72: Cleaner

Sheet Toilet Co-ordinates
A1: SITHEMBE TRANSPORTATION & PROJECTS | J1: 1-300 | L1: Toilet Co-ordinates
A3: LOCATION | B3: T No | C3: CO-ORDINATES | D3: LOCATION | E3: T No | F3: CO-ORDINATES | G3: LOCATION | H3: T No | I3: CO-ORDINATES | J3: LOCATION | K3: T No | L3: CO-ORDINATES | M3: LOCATION | N3: T No | O3: CO-ORDINATES
B4: 1 | D4: STINKWATER EXT 10 | E4: 61 | F4: 25°23'16.9"S 28°10'00.2"E | H4: 121 | K4: 181 | M4: BUFFER C | N4: 241 | O4: 25°28'12.8"S 28°08'23.8"E
B5: 2 | D5: STINKWATER EXT 10 | E5: 62 | F5: 25°23'15.2"S 28°10'00.1"E | H5: 122 | K5: 182 | M5: BUFFER C | N5: 242 | O5: 25°28'16.0"S 28°08'24.7"E
B6: 3 | D6: STINKWATER EXT 10 | E6: 63 | F6: 25°23'24.1"S 28°10'03.6"E | H6: 123 | K6: 183 | M6: BUFFER C | N6: 243 | O6: 25°28'18.5"S 28°08'25.1"E
B7: 4 | D7: STINKWATER EXT 10 | E7: 64 | F7: 25°23'24.2"S 28°10'03.5"E | H7: 124 | K7: 184 | M7: BUFFER C | N7: 244 | O7: 25°28'20.1"S 28°08'23.7"E
B8: 5 | D8: STINKWATER EXT 10 | E8: 65 | F8: 25°23'33.2"S 28°10'14.6"E | H8: 125 | K8: 185 | M8: BUFFER C | N8: 245 | O8: 25°28'17.3"S 28°08'25.3"E
B9: 6 | D9: STINKWATER EXT 10 | E9: 66 | F9: 25°23'25.3"S 28°10'09.2"E | H9: 126 | K9: 186 | M9: BUFFER C | N9: 246 | O9: 25°28'17.3"S 28°08'25.3"E
B10: 7 | D10: STINKWATER EXT 10 | E10: 67 | F10: 25°23'33.2"S 28°10'14.6"E | H10: 127 | K10: 187 | M10: PIENAARSPOORT | N10: 247 | O10: 25°27'45.4"S 28°08'11.7"E
B11: 8 | D11: STINKWATER EXT 10 | E11: 68 | F11: 25°23'24.2"S 28°10'07.5"E | H11: 128 | K11: 188 | M11: PIENAARSPOORT | N11: 248 | O11: 25°27'48.8"S 28°08'15.0"E
B12: 9 | D12: STINKWATER EXT 10 | E12: 69 | F12: 25°23'22.1"S 28°10'06.0"E | H12: 129 | K12: 189 | N12: 249
B13: 10 | D13: STINKWATER EXT 10 | E13: 70 | F13: 25°23'19.9"S 28°10'06.8"E | H13: 130 | K13: 190 | M13: PIENAARSPOORT | N13: 250 | O13: 25°27'54.3"S 28°07'59.8"E
B14: 11 | D14: STINKWATER EXT 10 | E14: 71 | F14: 25°23'21.4"S 28°10'08.0"E | H14: 131 | K14: 191 | M14: PIENAARSPOORT | N14: 251 | O14: 25°27'44.8"S 28°08'15.2"E
B15: 12 | D15: STINKWATER EXT 10 | E15: 72 | F15: 25°23'20.1"S 28°10'10.0"E | H15: 132 | K15: 192 | M15: PIENAARSPOORT | N15: 252 | O15: 25°27'48.8"S 28°08'00.8"E
B16: 13 | D16: STINKWATER EXT 10 | E16: 73 | F16: 25°23'23.2"S 28°10'10.8"E | H16: 133 | K16: 193 | M16: PIENAARSPOORT | N16: 253 | O16: 25°27'46.0"S 28°08'12.9"E
B17: 14 | D17: STINKWATER EXT 10 | E17: 74 | F17: 25°23'33.2"S 28°10'14.5"E | H17: 134 | K17: 194 | M17: PIENAARSPOORT | N17: 254 | O17: 25°27'49.9"S 28°08'15.2"E
A18: GREENFIELDS (LEFIKA CAMP | B18: 15 | C18: 25°24'14.4"S 28°14'42.2"E | D18: STINKWATER EXT 10 | E18: 75 | F18: 25°23'21.1"S 28°10'13.4"E | H18: 135 | K18: 195 | M18: PIENAARSPOORT | N18: 255 | O18: 25°27'45.8"S 28°08'13.1"E
A19: GREENFIELDS (LEFIKA CAMP | B19: 16 | C19: 25°24'15.2"S 28°14'44.0"E | D19: STINKWATER EXT 10 | E19: 76 | F19: 25°23'33.2"S 28°10'14.6"E | H19: 136 | K19: 196 | M19: PIENAARSPOORT | N19: 256 | O19: 25°27'44.8"S 28°07'55.7"E
A20: GREENFIELDS (LEFIKA CAMP | B20: 17 | C20: 25°24'16.9"S 28°14'41.9"E | D20: STINKWATER EXT 10 | E20: 77 | F20: 25°23'33.2"S 28°10'14.6"E | H20: 137 | K20: 197 | M20: PIENAARSPOORT | N20: 257 | O20: 25°27'45.8"S 28°08'13.1"E
A21: GREENFIELDS (LEFIKA CAMP | B21: 18 | C21: 25°24'21.8"S 28°14'34.1"E | D21: STINKWATER EXT 10 | E21: 78 | F21: 25°23'23.4"S 28°10'18.6"E | H21: 138 | K21: 198 | M21: PIENAARSPOORT | N21: 258 | O21: 25°27'44.8"S 28°07'55.7"E
A22: GREENFIELDS (LEFIKA CAMP | B22: 19 | C22: 25°24'23.5"S 28°14'33.7"E | D22: STINKWATER EXT 10 | E22: 79 | F22: 25°23'33.2"S 28°10'14.6"E | H22: 139 | K22: 199 | N22: 259
A23: HAMMANSKRAAL EXT 4 | B23: 20 | C23: 25°24'33.5"S 28°13'29.8"E | D23: STINKWATER EXT 10 | E23: 80 | F23: 25°23'21.8"S 28°10'16.6"E | H23: 140 | K23: 200 | N23: 260
A24: HAMMANSKRAAL EXT 4 | B24: 21 | C24: 25°24'37.4"S 28°13'29.5"E | D24: STINKWATER EXT 10 | E24: 81 | F24: 25°23'19.8"S 28°10'16.2"E | H24: 141 | J24: PHOMOLONG PHASE1 | K24: 201 | L24: 25°24'17.0"S 28°13'20.9"E | N24: 261
A25: HAMMANSKRAAL EXT 4 | B25: 22 | C25: 25°24'37.7"S 28°13'21.3"E | D25: STINKWATER EXT 10 | E25: 82 | F25: 25°23'20.3"S 28°10'17.2"E | H25: 142 | J25: PHOMOLONG PHASE1 | K25: 202 | L25: 25°24'13.4"S 28°13'22.6"E | N25: 262
A26: HAMMANSKRAAL EXT 4 | B26: 23 | C26: 25°24'35.3"S 28°13'21.6"E | D26: STINKWATER EXT 10 | E26: 83 | F26: 25°23'19.0"S 28°10'22.5"E | H26: 143 | J26: PHOMOLONG PHASE1 | K26: 203 | L26: 25°24'11.6"S 28°13'40.6"E | N26: 263
A27: HAMMANSKRAAL EXT 4 | B27: 24 | C27: 25°24'37.6"S 28°13'21.2"E | D27: STINKWATER EXT 10 | E27: 84 | F27: 25°23'18.2"S 28°10'16.5"E | H27: 144 | J27: PHOMOLONG PHASE1 | K27: 204 | L27: 25°24'14.3"S 28°13'40.4"E | N27: 264
A28: HAMMANSKRAAL EXT 4 | B28: 25 | C28: 25°24'36.2"S 28°13'20.2"E | D28: STINKWATER EXT 10 | E28: 85 | F28: 25°23'33.2"S 28°10'14.6"E | H28: 145 | J28: PHOMOLONG PHASE1 | K28: 205 | L28: 25°24'08.3"S 28°13'43.5"E | N28: 265
A29: HAMMANSKRAAL EXT 4 | B29: 26 | C29: 25°24'27.3"S 28°13'24.1"E | D29: STINKWATER EXT 10 | E29: 86 | F29: 25°23'17.7"S 28°10'21.3"E | H29: 146 | J29: PHOMOLONG PHASE1 | K29: 206 | L29: 25°24'08.3"S 28°13'43.5"E | N29: 266
A30: HAMMANSKRAAL EXT 4 | B30: 27 | C30: 25°24'42.1"S 28°13'36.4"E | D30: STINKWATER EXT 10 | E30: 87 | F30: 25°23'16.0"S 28°10'25.7"E | H30: 147 | J30: PHOMOLONG PHASE1 | K30: 207 | L30: 25°24'02.5"S 28°13'42.4"E | M30: PIENAARSPOORT | N30: 267 | O30: 25°27'41.4"S 28°08'19.8"E
A31: STINKWATER EXT 10 | B31: 28 | C31: 25°23'25.1"S 28°09'56.5"E | D31: STINKWATER EXT 10 | E31: 88 | F31: 25°23'25.8"S 28°09'59.9"E | H31: 148 | J31: PHOMOLONG PHASE1 | K31: 208 | L31: 25°24'07.0"S 28°13'34.3"E | N31: 268
A32: STINKWATER EXT 10 | B32: 29 | C32: 25°23'24.8"S 28°09'55.1"E | D32: STINKWATER EXT 10 | E32: 89 | F32: 25°23'33.2"S 28°10'14.6"E | H32: 149 | J32: PHOMOLONG PHASE1 | K32: 209 | L32: 25°24'04.1"S 28°13'28.6"E | N32: 269
A33: STINKWATER EXT 10 | B33: 30 | C33: 25°23'22.8"S 28°09'55.4"E | D33: STINKWATER EXT 10 | E33: 90 | F33: 25°23'17.0"S 28°10'05.8"E | H33: 150 | J33: PHOMOLONG PHASE1 | K33: 210 | L33: 25°24'07.0"S 28°13'32.2"E | N33: 270
A34: STINKWATER EXT 10 | B34: 31 | C34: 25°23'23.9"S 28°09'56.8"E | D34: STINKWATER EXT 10 | E34: 91 | F34: 25°23'18.2"S 28°10'07.5"E | H34: 151 | J34: PHOMOLONG PHASE1 | K34: 211 | L34: 25°24'07.0"S 28°13'34.3"E | M34: PIENAARSPOORT | N34: 271 | O34: 25°27'45.4"S 28°08'11.7"E
A35: STINKWATER EXT 10 | B35: 32 | C35: 25°23'23.9"S 28°09'56.8"E | D35: STINKWATER EXT 10 | E35: 92 | F35: 25°23'18.7"S 28°10'10.8"E | H35: 152 | J35: PHOMOLONG PHASE1 | K35: 212 | L35: 25°24'03.1"S 28°13'29.6"E | M35: PIENAARSPOORT | N35: 272 | O35: 25°27'46.0"S 28°07'55.2"E
A36: STINKWATER EXT 10 | B36: 33 | C36: 25°23'23.8"S 28°09'58.2"E | D36: STINKWATER EXT 10 | E36: 93 | F36: 25°23'22.2"S 28°10'14.9"E | H36: 153 | J36: PHOMOLONG PHASE1 | K36: 213 | L36: 25°23'44.5"S 28°13'28.3"E | N36: 273
A37: STINKWATER EXT 10 | B37: 34 | C37: 25°23'24.1"S 28°09'59.2"E | D37: STINKWATER EXT 10 | E37: 94 | F37: 25°23'33.2"S 28°10'14.6"E | G37: HAMMANSKRAAL PORTION 9& 10 | H37: 154 | I37: 25°21'48.9"S 28°15'15.9"E | J37: PHOMOLONG PHASE1 | K37: 214 | L37: 25°24'16.4"S 28°13'10.5"E | M37: PIENAARSPOORT | N37: 274 | O37: 25°27'51.6"S 28°08'04.2"E
A38: STINKWATER EXT 10 | B38: 35 | C38: 25°23'24.2"S 28°09'59.4"E | D38: STINKWATER EXT 10 | E38: 95 | F38: 25°23'20.9"S 28°10'21.4"E | G38: HAMMANSKRAAL PORTION 9& 10 | H38: 155 | I38: 25°21'48.9"S 28°15'15.9"E | J38: PHOMOLONG PHASE1 | K38: 215 | L38: 25°24'20.0"S 28°13'09.0"E | M38: PIENAARSPOORT | N38: 275 | O38: 25°27'51.6"S 28°07'59.9"E
A39: STINKWATER EXT 10 | B39: 36 | C39: 25°23'24.2"S 28°09'59.4"E | D39: STINKWATER EXT 10 | E39: 96 | F39: 25°23'16.0"S 28°10'25.7"E | H39: 156 | J39: PHOMOLONG PHASE1 | K39: 216 | L39: 25°24'12.4"S 28°13'23.9"E | M39: PIENAARSPOORT | N39: 276 | O39: 25°27'46.5"S 28°07'55.2"E
A40: STINKWATER EXT 10 | B40: 37 | C40: 25°23'23.3"S 28°09'59.9"E | D40: STINKWATER EXT 10 | E40: 97 | F40: 25°23'33.2"S 28°10'14.6"E | H40: 157 | J40: PHOMOLONG PHASE1 | K40: 217 | L40: 25°24'13.9"S 28°13'21.1"E | M40: PIENAARSPOORT | N40: 277
A41: STINKWATER EXT 10 | B41: 38 | C41: 25°23'23.2"S 28°09'59.7"E | E41: 98 | H41: 158 | J41: PHOMOLONG PHASE1 | K41: 218 | L41: 25°24'03.3"S 28°13'23.1"E | M41: PIENAARSPOORT | N41: 278 | O41: 25°27'53.4"S 28°07'56.7"E
...
